# Higher-Order Functions and `catchAsync` Utility

## Higher-Order Functions
A **higher-order function** is a function that can do one of two things:
1. **Take other functions as input** (as arguments).
2. **Return a function as its output**.

Let’s break this down step by step with simple examples.

### 1. Higher-Order Function Takes a Function as an Input (Argument)
Imagine you have a function that greets people by their name:

```javascript
const greet = (name) => `Hello, ${name}!`;
```

Now, let’s create another function called `callWithGreeting`. This function **takes the `greet` function** as an argument, uses it, and returns the greeting:

```javascript
const callWithGreeting = (name, greetFunction) => {
  return greetFunction(name); // Calls the passed function with the name
};

console.log(callWithGreeting("Alice", greet)); // Output: Hello, Alice!
```

**Why is `callWithGreeting` a higher-order function?**
- It **takes a function (`greet`) as an argument**. It’s like a machine that can work with different recipes (functions) you provide.

---

### 2. Higher-Order Function Returns Another Function
Here’s an example where a function creates and **returns** a new function:

```javascript
const multiplyBy = (x) => {
  return (y) => x * y; // Returns a new function that multiplies by x
};

const double = multiplyBy(2); // `double` is now a function that multiplies by 2
console.log(double(5)); // Output: 10
```

**Why is `multiplyBy` a higher-order function?**
- It **returns a new function** (like a recipe that creates another recipe).
- The returned function `double` is created when you call `multiplyBy(2)`.

---

## `catchAsync` Utility
The `catchAsync` utility is a middleware function used in Express.js for handling errors in asynchronous route handlers. It simplifies error handling by automatically catching any errors and passing them to the error-handling middleware.

### How `catchAsync` Works

#### Code Implementation:
```typescript
const catchAsync = (fn: RequestHandler) => {
  return (req: Request, res: Response, next: NextFunction) => {
    Promise.resolve(fn(req, res, next)).catch(next);
  };
};
```

#### Breakdown of the Code:
1. **Function Declaration**:
   ```typescript
   const catchAsync = (fn: RequestHandler) => { ... };
   ```
   The `catchAsync` function is a higher-order function. It takes another function `fn` (a request handler) as its argument and returns a new function with added error handling.

2. **Wrapper for the Request Handler**:
   ```typescript
   return (req: Request, res: Response, next: NextFunction) => { ... };
   ```
   The returned function replaces the original handler. It uses the standard Express parameters: `req`, `res`, and `next`.

3. **Handling Async Errors**:
   ```typescript
   Promise.resolve(fn(req, res, next)).catch((error) => next(error));
   ```
   - `Promise.resolve(fn(req, res, next))`: Ensures that `fn` is wrapped in a promise. Even if `fn` is not asynchronous, it gets converted to a resolved promise.
   - `.catch((error) => next(error))`: If an error occurs, it is caught and passed to the next middleware using `next(error)`.

4. **Error Handling**:
   By passing errors to `next(error)`, Express’s error-handling middleware can process them (typically defined as `app.use((err, req, res, next) => { ... })`).

---

### Why is `catchAsync` a Higher-Order Function?
The `catchAsync` utility is a **higher-order function** because:
1. **It takes a function as input**: The `fn` parameter is the original route handler.
2. **It returns a new function**: This wrapper executes `fn` and handles errors using `Promise.resolve(...).catch(next)`.

---

### Benefits of Using `catchAsync`
In Express, route handlers for asynchronous operations often involve promises (e.g., database calls, external APIs). Without `catchAsync`, you’d need to write repetitive `try...catch` blocks in every route handler to handle errors.

#### Example Without `catchAsync`:
```typescript
app.get('/user', async (req, res, next) => {
  try {
    const user = await getUserFromDatabase();
    res.json(user);
  } catch (error) {
    next(error);
  }
});
```

#### Example With `catchAsync`:
```typescript
app.get('/user', catchAsync(async (req, res, next) => {
  const user = await getUserFromDatabase();
  res.json(user);
}));
```

With `catchAsync`, the error handling is streamlined. You don’t need to manually wrap each handler in a `try...catch`, making your code cleaner and easier to maintain.

